Workbook

Sheet Placar
A1: Placar da checagem — Debate Globo, 2º turno 2026 (23/10/2026)
A2: Flávio Bolsonaro (PL) × Lula (PT) · cada declaração pesquisada por um agente e conferida por outro agente independente
A4: Veredito | B4: Flávio Bolsonaro | C4: Lula | D4: Total
A5: Verdadeiro | B5: =COUNTIFS(Checagens!$B$2:$B$92,"Flávio",Checagens!$E$2:$E$92,A5) | C5: =COUNTIFS(Checagens!$B$2:$B$92,"Lula",Checagens!$E$2:$E$92,A5) | D5: =B5+C5
A6: Verdadeiro, mas impreciso | B6: =COUNTIFS(Checagens!$B$2:$B$92,"Flávio",Checagens!$E$2:$E$92,A6) | C6: =COUNTIFS(Checagens!$B$2:$B$92,"Lula",Checagens!$E$2:$E$92,A6) | D6: =B6+C6
A7: Exagerado | B7: =COUNTIFS(Checagens!$B$2:$B$92,"Flávio",Checagens!$E$2:$E$92,A7) | C7: =COUNTIFS(Checagens!$B$2:$B$92,"Lula",Checagens!$E$2:$E$92,A7) | D7: =B7+C7
A8: Falso | B8: =COUNTIFS(Checagens!$B$2:$B$92,"Flávio",Checagens!$E$2:$E$92,A8) | C8: =COUNTIFS(Checagens!$B$2:$B$92,"Lula",Checagens!$E$2:$E$92,A8) | D8: =B8+C8
A9: Sem evidência | B9: =COUNTIFS(Checagens!$B$2:$B$92,"Flávio",Checagens!$E$2:$E$92,A9) | C9: =COUNTIFS(Checagens!$B$2:$B$92,"Lula",Checagens!$E$2:$E$92,A9) | D9: =B9+C9
A10: Total de declarações checadas | B10: =SUM(B5:B9) | C10: =SUM(C5:C9) | D10: =B10+C10
A12: RESUMO
A13: Verdades (Verdadeiro + Verdadeiro, mas impreciso) | B13: =B5+B6 | C13: =C5+C6 | D13: =B13+C13
A14: Falsas (Falso) | B14: =B8 | C14: =C8 | D14: =B14+C14
A15: Exageradas | B15: =B7 | C15: =C7 | D15: =B15+C15
A16: Sem evidência | B16: =B9 | C16: =C9 | D16: =B16+C16
A17: % de verdades | B17: =IF(B10=0,0,B13/B10) | C17: =IF(C10=0,0,C13/C10) | D17: =IF(D10=0,0,D13/D10)
A18: % de falsas + exageradas | B18: =IF(B10=0,0,(B14+B15)/B10) | C18: =IF(C10=0,0,(C14+C15)/C10) | D18: =IF(D10=0,0,(D14+D15)/D10)
A20: Revisões em que o agente revisor discordou da pesquisa inicial | B20: =COUNTIF(Checagens!$I$2:$I$92,"Não")
A22: Critérios: "verdades" = Verdadeiro + Verdadeiro, mas impreciso; "falsas" = Falso. Exagerado e Sem evidência aparecem à parte. Detalhes na aba Metodologia.

Sheet Placar Promessas
A1: Viabilidade das promessas, mandato 2027-2030
A2: Viabilidade (%) = chance estimada de a promessa ser cumprida em boa parte até 2030, considerando custo/espaço fiscal, exigências legais, competência federativa, prazo e realidade regional.
A4: Indicador | B4: Flávio Bolsonaro | C4: Lula | D4: Total
A5: Promessas analisadas | B5: =COUNTIF(Promessas!$B$2:$B$41,"Flávio") | C5: =COUNTIF(Promessas!$B$2:$B$41,"Lula") | D5: =B5+C5
A6: Viabilidade média | B6: =IFERROR(AVERAGEIF(Promessas!$B$2:$B$41,"Flávio",Promessas!$F$2:$F$41),0) | C6: =IFERROR(AVERAGEIF(Promessas!$B$2:$B$41,"Lula",Promessas!$F$2:$F$41),0) | D6: =AVERAGE(Promessas!$F$2:$F$41)
A7: Viabilidade mais alta | B7: =SUMPRODUCT(MAX((Promessas!$B$2:$B$41="Flávio")*Promessas!$F$2:$F$41)) | C7: =SUMPRODUCT(MAX((Promessas!$B$2:$B$41="Lula")*Promessas!$F$2:$F$41)) | D7: =MAX(Promessas!$F$2:$F$41)
A8: Viabilidade mais baixa | B8: =SUMPRODUCT(MIN((Promessas!$B$2:$B$41="Flávio")*Promessas!$F$2:$F$41+(Promessas!$B$2:$B$41<>"Flávio")*2)) | C8: =SUMPRODUCT(MIN((Promessas!$B$2:$B$41="Lula")*Promessas!$F$2:$F$41+(Promessas!$B$2:$B$41<>"Lula")*2)) | D8: =MIN(Promessas!$F$2:$F$41)
A9: Alta viabilidade (70-100%) | B9: =COUNTIFS(Promessas!$B$2:$B$41,"Flávio",Promessas!$G$2:$G$41,"Alta") | C9: =COUNTIFS(Promessas!$B$2:$B$41,"Lula",Promessas!$G$2:$G$41,"Alta") | D9: =B9+C9
A10: Média viabilidade (40-69%) | B10: =COUNTIFS(Promessas!$B$2:$B$41,"Flávio",Promessas!$G$2:$G$41,"Média") | C10: =COUNTIFS(Promessas!$B$2:$B$41,"Lula",Promessas!$G$2:$G$41,"Média") | D10: =B10+C10
A11: Baixa viabilidade (0-39%) | B11: =COUNTIFS(Promessas!$B$2:$B$41,"Flávio",Promessas!$G$2:$G$41,"Baixa") | C11: =COUNTIFS(Promessas!$B$2:$B$41,"Lula",Promessas!$G$2:$G$41,"Baixa") | D11: =B11+C11
A12: % de promessas com alta viabilidade | B12: =IF(B5=0,0,B9/B5) | C12: =IF(C5=0,0,C9/C5) | D12: =IF(D5=0,0,D9/D5)
A15: Viabilidade média por tema
A16: Tema (grupo) | B16: Flávio Bolsonaro | C16: Lula | D16: Nº promessas
A17: Agro | B17: =IFERROR(AVERAGEIFS(Promessas!$F$2:$F$41,Promessas!$B$2:$B$41,"Flávio",Promessas!$R$2:$R$41,A17),"—") | C17: =IFERROR(AVERAGEIFS(Promessas!$F$2:$F$41,Promessas!$B$2:$B$41,"Lula",Promessas!$R$2:$R$41,A17),"—") | D17: =COUNTIF(Promessas!$R$2:$R$41,A17)
A18: Apostas | B18: =IFERROR(AVERAGEIFS(Promessas!$F$2:$F$41,Promessas!$B$2:$B$41,"Flávio",Promessas!$R$2:$R$41,A18),"—") | C18: =IFERROR(AVERAGEIFS(Promessas!$F$2:$F$41,Promessas!$B$2:$B$41,"Lula",Promessas!$R$2:$R$41,A18),"—") | D18: =COUNTIF(Promessas!$R$2:$R$41,A18)
A19: Economia | B19: =IFERROR(AVERAGEIFS(Promessas!$F$2:$F$41,Promessas!$B$2:$B$41,"Flávio",Promessas!$R$2:$R$41,A19),"—") | C19: =IFERROR(AVERAGEIFS(Promessas!$F$2:$F$41,Promessas!$B$2:$B$41,"Lula",Promessas!$R$2:$R$41,A19),"—") | D19: =COUNTIF(Promessas!$R$2:$R$41,A19)
A20: Educação | B20: =IFERROR(AVERAGEIFS(Promessas!$F$2:$F$41,Promessas!$B$2:$B$41,"Flávio",Promessas!$R$2:$R$41,A20),"—") | C20: =IFERROR(AVERAGEIFS(Promessas!$F$2:$F$41,Promessas!$B$2:$B$41,"Lula",Promessas!$R$2:$R$41,A20),"—") | D20: =COUNTIF(Promessas!$R$2:$R$41,A20)
A21: Indígenas | B21: =IFERROR(AVERAGEIFS(Promessas!$F$2:$F$41,Promessas!$B$2:$B$41,"Flávio",Promessas!$R$2:$R$41,A21),"—") | C21: =IFERROR(AVERAGEIFS(Promessas!$F$2:$F$41,Promessas!$B$2:$B$41,"Lula",Promessas!$R$2:$R$41,A21),"—") | D21: =COUNTIF(Promessas!$R$2:$R$41,A21)
A22: Infraestrutura | B22: =IFERROR(AVERAGEIFS(Promessas!$F$2:$F$41,Promessas!$B$2:$B$41,"Flávio",Promessas!$R$2:$R$41,A22),"—") | C22: =IFERROR(AVERAGEIFS(Promessas!$F$2:$F$41,Promessas!$B$2:$B$41,"Lula",Promessas!$R$2:$R$41,A22),"—") | D22: =COUNTIF(Promessas!$R$2:$R$41,A22)
A23: Mobilidade | B23: =IFERROR(AVERAGEIFS(Promessas!$F$2:$F$41,Promessas!$B$2:$B$41,"Flávio",Promessas!$R$2:$R$41,A23),"—") | C23: =IFERROR(AVERAGEIFS(Promessas!$F$2:$F$41,Promessas!$B$2:$B$41,"Lula",Promessas!$R$2:$R$41,A23),"—") | D23: =COUNTIF(Promessas!$R$2:$R$41,A23)
A24: Mulheres | B24: =IFERROR(AVERAGEIFS(Promessas!$F$2:$F$41,Promessas!$B$2:$B$41,"Flávio",Promessas!$R$2:$R$41,A24),"—") | C24: =IFERROR(AVERAGEIFS(Promessas!$F$2:$F$41,Promessas!$B$2:$B$41,"Lula",Promessas!$R$2:$R$41,A24),"—") | D24: =COUNTIF(Promessas!$R$2:$R$41,A24)
A25: Nordeste | B25: =IFERROR(AVERAGEIFS(Promessas!$F$2:$F$41,Promessas!$B$2:$B$41,"Flávio",Promessas!$R$2:$R$41,A25),"—") | C25: =IFERROR(AVERAGEIFS(Promessas!$F$2:$F$41,Promessas!$B$2:$B$41,"Lula",Promessas!$R$2:$R$41,A25),"—") | D25: =COUNTIF(Promessas!$R$2:$R$41,A25)
A26: Norte | B26: =IFERROR(AVERAGEIFS(Promessas!$F$2:$F$41,Promessas!$B$2:$B$41,"Flávio",Promessas!$R$2:$R$41,A26),"—") | C26: =IFERROR(AVERAGEIFS(Promessas!$F$2:$F$41,Promessas!$B$2:$B$41,"Lula",Promessas!$R$2:$R$41,A26),"—") | D26: =COUNTIF(Promessas!$R$2:$R$41,A26)
A27: Saúde | B27: =IFERROR(AVERAGEIFS(Promessas!$F$2:$F$41,Promessas!$B$2:$B$41,"Flávio",Promessas!$R$2:$R$41,A27),"—") | C27: =IFERROR(AVERAGEIFS(Promessas!$F$2:$F$41,Promessas!$B$2:$B$41,"Lula",Promessas!$R$2:$R$41,A27),"—") | D27: =COUNTIF(Promessas!$R$2:$R$41,A27)
A28: Segurança | B28: =IFERROR(AVERAGEIFS(Promessas!$F$2:$F$41,Promessas!$B$2:$B$41,"Flávio",Promessas!$R$2:$R$41,A28),"—") | C28: =IFERROR(AVERAGEIFS(Promessas!$F$2:$F$41,Promessas!$B$2:$B$41,"Lula",Promessas!$R$2:$R$41,A28),"—") | D28: =COUNTIF(Promessas!$R$2:$R$41,A28)
... A31: Trabalho | B31: =IFERROR(AVERAGEIFS(Promessas!$F$2:$F$41,Promessas!$B$2:$B$41,"Flávio",Promessas!$R$2:$R$41,A31),"—") | C31: =IFERROR(AVERAGEIFS(Promessas!$F$2:$F$41,Promessas!$B$2:$B$41,"Lula",Promessas!$R$2:$R$41,A31),"—") | D31: =COUNTIF(Promessas!$R$2:$R$41,A31)
A33: "—" = o candidato não fez promessa nesse tema. A média geral pesa igualmente cada promessa; o detalhe está na aba Promessas.

Sheet Checagens
A1: ID | B1: Candidato | C1: Tempo no vídeo | D1: Declaração (resumo) | E1: Veredito final | F1: Explicação (resumo) | G1: Confiança | H1: Veredito da pesquisa inicial | I1: Revisor concordou? | J1: Nota do revisor independente | K1: Principais fontes
A2: F01 | B2: Flávio | C2: 00:07 | D2: O governo Bolsonaro recebeu o país em 2019 com cerca de 14.000 obras inacabadas e entregou com pouco mais de 8.000. | E2: Verdadeiro, mas impreciso | F2: Os números se aproximam dos levantamentos do TCU. A auditoria do Acórdão 1.079/2019, feita entre 2017 e 2019, achou cerca de 14 mil obras paralisadas num total de 38 mil (cerca de 37%). O levantamento julgado pelo TCU em 18/10/2023, que O Povo associa à situação de 2022, achou 8.603 obras paralisadas, mas num universo bem menor, de 21.007. A queda absoluta existe. A proporção de obras paradas, porém, subiu de cerca de 29% em 2020 (7.862 de 27.126) para 41%. O TCU também concluiu que não existiu, entre 2019 e 2022, política pública para resolver o problema das obras paralisadas. | G2: Alta | H2: Verdadeiro, mas impreciso | I2: Sim | J2: REAVALIADO SEM FONTES ENVIESADAS. Veredito mantido. Saíram o 8.674 e o 14,4 mil em 38,4 mil, que só vinham da Gazeta do Povo. Entraram os números oficiais do TCU: 8.603 em 21.007 e cerca de 14 mil em 38 mil. O Jornal Opção não foi usado. Revisor: Abri todas as fontes citadas, e elas são permitidas e confirmam o que o agente afirma. O 8.603/21.007 e os 29% e 41% estão na notícia do TCU. O 14 mil em 38 mil está no relatório do TCU de 2019. A frase sobre a falta de política pública entre 2019 e 2022 está em O Povo. Um ajuste: a notícia do TCU dá como data dos dados a sessão de 18/10/2023, e a ligação com 2022 vem de O Povo. O texto foi ajustado para refletir isso. Nenhum dado depende de fonte excluída. | K2: https://portal.tcu.gov.br/imprensa/noticias/brasil-tem-86-mil-obras-paralisadas-financiadas-com-recursos-federais https://sites.tcu.gov.br/relatorio-de-politicas/2019/area_12.htm https://www.opovo.com.br/noticias/economia/2023/10/18/tcu-diz-que-nao-existiu-entre-2019-e-2022-politicas-para-obras-paralisadas-e-cobra-medidas.html
A3: F02 | B3: Flávio | C3: 00:07 | D3: O TCU acaba de soltar (2026) relatório apontando mais de 11.500 obras paralisadas no atual governo. | E3: Verdadeiro, mas impreciso | F3: Em 30/07/2025, o TCU divulgou que 11.469 das 22.621 obras com recursos federais (50,7%) estavam paralisadas em abril de 2025. O número fica um pouco abaixo dos 'mais de 11.500' citados, e o relatório é de 2025, não de 2026. O estoque também reúne obras iniciadas em gestões anteriores: das 5.505 obras iniciadas entre abril de 2024 e abril de 2025, cerca de 1,2 mil (22%) estavam paradas. | G3: Alta | H3: Verdadeiro, mas impreciso | I3: Sim | J3: REAVALIADO SEM FONTES ENVIESADAS. Nada mudou na substância. Revisor: Confirmei no TCU e no Viva os números 11.469 de 22.621 (50,7%), a data de 30/07/2025, a referência a abril de 2025 e as cerca de 1,2 mil paradas entre as 5.505 obras recentes. Acrescentei à explicação que 11.469 fica levemente abaixo de 'mais de 11.500'. Nenhum dado depende de fonte excluída. | K3: https://portal.tcu.gov.br/imprensa/noticias/metade-das-obras-financiadas-com-recursos-federais-estao-paradas https://viva.com.br/noticias/brasil-tem-mais-de-11-mil-obras-paradas-para-tcu-volume-e-preocupante.html
A4: F03 | B4: Flávio | C4: 00:10 | D4: Regra do governo Bolsonaro garante pedágio zero para motociclistas em todas as novas concessões federais de rodovias. | E4: Exagerado | F4: A Portaria 104/2021 do Ministério da Infraestrutura fixou como diretriz a isenção de pedágio para motos nos editais de 11 rodovias federais então em licitação, como Dutra, Fernão Dias e BR-040. Não é uma regra que garanta a isenção em todas as novas concessões federais: cada contrato define a questão separadamente. A ideia de valer para todas foi uma promessa de Bolsonaro. | G4: Média | H4: Verdadeiro, mas impreciso | I4: Não | J4: A base da pesquisa original está correta, mas o InfoMoney confirma que a portaria se limitava a 11 rodovias específicas e que cada contrato é negociado separadamente. Por isso a palavra 'garante' com 'todas as novas concessões' infla a medida, e mudei o veredito de 'Verdadeiro, mas impreciso' para 'Exagerado'. Descartei as fontes de blogs de motos. | K4: https://www.infomoney.com.br/?p=1881372 https://oespecialista.safra.com.br/tcu-aprova-concessao-da-dutra-e-isencao-de-pedagio-para-motos/ https://www.motoo.com.br/novas-concessoes-de-rodovias-federais-terao-isencao-de-pedagio-para-motos/ https://www.agazeta.com.br/es/economia/motos-ficarao-livres-de-pagar-pedagio-na-br-262-apos-concessao-0721
A5: F04 | B5: Flávio | C5: 00:10 | D5: O governo Bolsonaro instalou mais de 21.300 pontos de internet, em mais de 3.100 cidades, atendendo mais de 11 milhões de brasileiros (escolas, unidades de saúde, aldeias). | E5: Verdadeiro, mas impreciso | F5: Os números batem com o balanço oficial do Ministério das Comunicações. O texto foi publicado no portal gov.br em 19/12/2022 e republicado pelo NIC.br em 20/12/2022; abri a página. Segundo ele, o Wi-Fi Brasil tinha 21,3 mil pontos de internet gratuita, atendia mais de 11 milhões de brasileiros em cerca de 3,2 mil cidades, e 16.195 conexões (76,2%) ficavam em escolas. Os 21.300 pontos, as mais de 3.100 cidades e os mais de 11 milhões de pessoas citados por Flávio estão, portanto, corretos. A imprecisão está em dizer que o governo Bolsonaro 'instalou' todos esses pontos. O Wi-Fi Brasil é a continuação do antigo programa GESAC, criado em 2002, e parte das conexões já existia antes de 2019. Em abril de 2021 a Agência Brasil já falava em mais de 13 mil pontos. A grande expansão aconteceu em 2021-2022, mas o total acumulado não foi instalado só nessa gestão. O balanço que abri não traz números separados de unidades de saúde e aldeias, apenas a menção genérica. | G5: Alta | H5: Verdadeiro, mas impreciso | I5: Sim | J5: RECHECADO (2ª rodada). Concordo com o veredito e agora há confirmação do número exato, que o agente anterior não havia achado: o balanço oficial de dezembro de 2022 confirma 21,3 mil pontos, cerca de 3,2 mil cidades e mais de 11 milhões de pessoas. A ressalva sobre a origem no GESAC (2002) continua válida. Observação: o limite de buscas da sessão se esgotou depois da primeira consulta, então a revisão se apoiou em páginas abertas com WebFetch. | K5: https://www.nic.br/noticia/na-midia/mais-de-21-3-mil-pontos-de-internet-do-wi-fi-brasil-sao-instalados/ https://agenciabrasil.ebc.com.br/geral/noticia/2021-04/programa-leva-internet-areas-remotas-do-pais https://www.minhaoperadora.com.br/2022/06/governo-entregou-mais-de-17-mil-pontos-wi-fi-a-populacao.html https://agenciasebrae.com.br/inovacao/wi-fi-brasil-sebrae-inicia-instalacao-dos-pontos-de-conexao
A6: F05 | B6: Flávio | C6: 00:18 | D6: Lula implementou a carga tributária mais alta da história do país. | E6: Verdadeiro, mas impreciso | F6: Pelos dados preliminares do Tesouro Nacional (abril de 2026), a carga tributária bruta de 2025 foi de 32,4% do PIB, a maior da série iniciada em 2010. Chamar isso de 'mais alta da história' vale só para essa série. A alta sobre 2024 foi pequena e se deve em parte ao comportamento da arrecadação, não apenas a novos tributos criados pelo governo. | G6: Média | H6: Verdadeiro, mas impreciso | I6: Sim | J6: Confirmei os 32,4% e que a série do Tesouro começa em 2010. A ressalva sobre séries anteriores, com outra metodologia, segue válida. As fontes usadas são portais secundários que reproduzem o Tesouro. Não acessei a nota oficial do Tesouro porque o limite de buscas acabou. | K6: https://www.reformatributaria.com/economia-reforma-tributaria-impactos/carga-tributaria-bate-recorde-em-2025-e-atinge-324-do-pib/ https://economicnewsbrasil.com.br/2026/04/11/carga-tributaria-brasil-2025-tesouro-dados/ https://www.contabeis.com.br/noticias/76330/carga-tributaria-do-brasil-atinge-recorde-de-32-4-do-pib-em-2025/
A7: F06 | B7: Flávio | C7: 00:18 | D7: A alíquota do novo IVA da reforma tributária é estimada em cerca de 28% e será o maior IVA do mundo; o governo já deveria ter enviado ao Congresso projeto definindo a alíquota. | E7: Verdadeiro, mas impreciso | F7: As estimativas do IVA dual ficaram em cerca de 28%: 27,97% no texto da Câmara e 28,55% após o Senado, segundo o relator Eduardo Braga. Isso supera os 27% da Hungria. Mas não há atraso no envio de projeto: pela lei complementar, se a alíquota de referência passar de 26,5%, o governo tem 90 dias a partir de dezembro de 2030 para enviar um projeto que reduza incentivos fiscais. | G7: Média | H7: Verdadeiro, mas impreciso | I7: Sim | J7: Confirmei no InfoMoney os 28,55%, a comparação com a Hungria e o prazo de 2030/2031. A segunda parte da fala é falsa. Mantive 'Verdadeiro, mas impreciso' porque o núcleo da afirmação, a alíquota de cerca de 28% e o maior IVA do mundo, se sustenta. Seria defensável também chamar a fala inteira de 'Exagerada'. | K7: https://www.infomoney.com.br/?p=2703795 https://www.moneytimes.com.br/brasil-tera-maior-aliquota-do-mundo-apos-reforma-tributaria-no-senado-jals/ https://edicao.correiobraziliense.com.br/correiobraziliense/2025/01/17/13530f/pdf/A02-POL-1701-DIG.pdf
A8: F07 | B8: Flávio | C8: 00:19 | D8: Foi Bolsonaro que estabeleceu o benefício mínimo de R$ 600 do Bolsa Família/Auxílio Brasil. | E8: Exagerado | F8: O governo Bolsonaro pagou o Auxílio Brasil de R$ 600 em 2022. O valor veio de um acréscimo temporário de R$ 200, aprovado pela chamada PEC das Bondades (ou PEC Kamikaze), que valia só até dezembro de 2022. Sem nova medida, o benefício voltaria a R$ 400 em janeiro de 2023. A manutenção dos R$ 600 em 2023 veio da PEC articulada pela equipe de transição de Lula, que ampliou o teto de gastos. O piso de R$ 600 por família, garantido por complementação, foi fixado pela Lei 14.601/2023, que recriou o Bolsa Família. Bolsonaro de fato pagou R$ 600, mas de forma temporária, e não estabeleceu o piso permanente. | G8: Alta | H8: Exagerado | I8: Sim | J8: REAVALIADO SEM FONTES ENVIESADAS. Veredito mantido. Saiu a Crusoé. A previsão do Orçamento de 2023 deu lugar ao dado confirmado de que o valor voltaria a R$ 400 em janeiro de 2023. Entrou a Lei 14.601/2023 como base do piso permanente. A referência ao número da EC 126 saiu. Revisor: O Correio Braziliense confirma a PEC das Bondades/Kamikaze e o acréscimo de R$ 200 válido até dezembro. O Jornal Contábil confirma a volta a R$ 400 sem nova medida e a PEC da equipe de Lula que ampliou o teto. A Câmara confirma o piso de R$ 600 por complementação na Lei 14.601/2023. A página do Planalto não abriu (timeout) e foi retirada das fontes, o que não muda o resultado porque a Câmara já confirma a lei. Tirei também o 'a partir de agosto', que nenhuma das fontes abertas confirma de forma explícita. Nenhum dado depende de fonte excluída. | K8: https://www.correiobraziliense.com.br/politica/2022/08/5029151-bolsonaro-rebate-lula-e-volta-a-prometer-auxilio-de-rs-600-em-2023.html https://jornalcontabil.com.br/noticia/este-sera-o-novo-valor-do-auxilio-brasil-2023-veja-agora/ https://www.camara.leg.br/noticias/973711-SANCIONADA-LEI-QUE-RECRIA-O-PROGRAMA-BOLSA-FAMILIA https://www.planalto.gov.br/ccivil_03/_ato2023-2026/2023/lei/l14601.htm
A9: F08 | B9: Flávio | C9: 00:20 | D9: Reduflação no governo Lula: dúzia de ovos virou caixa com 10, sabão em pó de 1 kg virou 800 g, barra de chocolate de 120 g virou 80 g, rolo de papel higiênico de 40 m virou 20 m. | E9: Exagerado | F9: A reduflação existe no Brasil e há casos documentados de caixas de ovos com 10 unidades, sabão em pó de 800 g e papel higiênico com menos metros. Mas é uma prática da indústria, anterior ao atual governo e que não resulta de política federal. Não encontrei os números exatos citados (chocolate de 120 g para 80 g, papel higiênico de 40 m para 20 m) como tendência geral. | G9: Média | H9: Exagerado | I9: Sim | J9: Concordo. O limite de buscas da sessão acabou, então não pude fazer busca nova. Lembro, de conhecimento prévio, que a regra federal que obriga avisar o consumidor sobre redução de quantidade (Portaria MJSP 392/2021) é de 2021, antes do atual governo. Isso reforça que a prática não começou com Lula. O link do ABCdoABC é de portal regional que repete um alerta do Procon; tem valor secundário. | K9: https://www.infomoney.com.br/?p=1885250 https://diariodonordeste.verdesmares.com.br/negocios/reduflacao-ocorre-mais-no-azeite-manteiga-e-cafe-aponta-estudo-veja-produtos-1.3531679 https://goias.gov.br/procon/wp-content/uploads/sites/19/2024/09/PLANILHA-GERAL-PESQUISA-DE-PRECOS-PRODUTOS-DE-LIMPEZA-E-HIGIENE-PESSOAL.pdf https://abcdoabc.com.br/procon-santo-andre-alerta-consumidores-sobre-reduflacao/
A10: F09 | B10: Flávio | C10: 00:19 | D10: O Brasil tem uma das maiores taxas de juros do mundo. | E10: Verdadeiro | F10: Com a Selic perto de 14,25% a 14,50% em 2026, o Brasil está entre os maiores juros nominais do mundo e em 1º ou 2º lugar em juros reais, segundo rankings citados pela imprensa econômica. | G10: Alta | H10: Verdadeiro | I10: Sim | J10: Concordo. Não consegui fazer busca nova porque o limite de buscas acabou. A afirmação é genérica ("uma das maiores") e condiz com o histórico sabido da Selic e com as reportagens citadas, que são de portais de notícias. | K10: https://www.poder360.com.br/poder-economia/mesmo-com-corte-brasil-tem-o-maior-juro-real-do-planeta/ https://www.moneytimes.com.br/selic-a-1450-brasil-segue-com-o-2o-maior-juro-real-do-mundo-mesmo-apos-corte-jcav/ https://www.poder360.com.br/poder-economia/brasil-mantem-maior-juro-real-do-mundo-diz-pesquisa/
A11: F10 | B11: Flávio | C11: 00:21 | D11: Lula chamou o agro de fascista e disse que as pessoas (do agro) têm que se ajoelhar aos seus pés. | E11: Verdadeiro, mas impreciso | F11: Em 2022, Lula disse que parte do agronegócio era "fascista e direitista" e depois afirmou que não quis generalizar. Segundo a pesquisa original, em 2026 ele também disse que o agro deveria "se ajoelhar" diante dele por causa dos recursos dados ao setor. Flávio junta as duas falas e generaliza para o agro inteiro. | G11: Média | H11: Verdadeiro, mas impreciso | I11: Sim | J11: Concordo com o veredito. A fala de 2022 sobre parte do agro ser fascista está bem documentada. Não consegui abrir a fonte da fala do "ajoelhar" (o Canal Rural bloqueou o acesso, erro 403) e o limite de buscas acabou. Por isso essa parte depende só da fonte original, o que reduz a confiança. | K11: https://www.poder360.com.br/eleicoes/lula-diz-que-nao-generalizou-ao-ligar-agro-ao-fascismo/ https://jornaldebrasilia.com.br/noticias/politica-e-poder/aliado-de-lula-no-agro-diz-que-petista-errou-e-precisa-se-desculpar-por-fala-sobre-fascismo/ https://www.canalrural.com.br/politica/tereza-cristina-rebate-lula-apos-fala-sobre-agro-isso-nao-se-faz-com-bravatas/
A12: F11 | B12: Flávio | C12: 00:24 | D12: Os juros reais do crédito do Plano Safra chegam perto de 20%, e o governo Lula contingencia recursos do seguro rural e do Plano Safra. | E12: Exagerado | F12: O bloqueio de recursos do seguro rural (PSR) em 2026 foi noticiado. Já os juros das linhas oficiais do Plano Safra 2026/27 estão bem abaixo de 20%: o Pronamp tem teto de 9% ao ano e o Pronaf é ainda mais barato. Descontada a inflação, o juro real das linhas equalizadas fica muito longe de 20%. | G12: Média | H12: Exagerado | I12: Sim | J12: Confirmei no Times Brasil e no AgFeed o teto de 9% do Pronamp e que nenhum dos dois fala em 20%. As duas reportagens não informam a taxa de 12,5% do custeio empresarial que a pesquisa original atribuiu a elas. Não consegui abrir a matéria do Canal Rural sobre o bloqueio de R$ 461,7 milhões (erro 403). O AgFeed mostra ainda que o volume de custeio caiu cerca de 11% em termos reais, o que dá alguma base à crítica de aperto no crédito. A parte dos juros de 20% continua sem sustentação para o crédito oficial. | K12: https://timesbrasil.com.br/empresas-e-negocios/agro/plano-safra-26-27-governo-eleva-credito-a-r-5251-bilhoes-e-impoe-taxa-maxima-de-juros-no-campo/ https://agfeed.com.br/economia/plano-safra-cresce-menos-que-a-inflacao-e-agricultura-empresarial-tera-menos-recursos-para-o-custeio https://www.canalrural.com.br/politica/bloqueio-de-r-4617-milhoes-no-psr-e-atribuido-a-restricoes-fiscais/ https://www.canalrural.com.br/politica/plano-safra-da-agricultura-familiar-preve-r-973-bilhoes-para-2026-2027/
... A92: L35 | B92: Lula | C92: 01:50 | D92: O governo Bolsonaro gastou cerca de 30% a mais no cartão corporativo que o governo Lula. | E92: Verdadeiro, mas impreciso | F92: Abri a matéria do Terra (24/10/2026), que é uma fonte permitida. Os números são estes: - Secretaria de Administração da Presidência: R$ 41,2 milhões com Bolsonaro (2019-2022) contra R$ 20,4 milhões com Lula (2023-2025). - Presidência, incluindo GSI e Abin: R$ 82,4 milhões contra R$ 45,2 milhões. - Governo federal inteiro: cerca de R$ 1 bilhão com Bolsonaro, em 4 anos, contra cerca de R$ 1,4 bilhão com Lula, em 3 anos. Desse total de Lula, R$ 1,1 bilhão (78%) foi para calamidades. Em valores totais, Bolsonaro gastou cerca de 82% a mais na Presidência e cerca de 102% a mais na Secretaria. Pela média anual (cálculo próprio), a diferença cai para cerca de 37% e 51%. No âmbito da Presidência, portanto, a ideia de que Bolsonaro gastou mais procede, e a média anual fica perto do '30%' citado. Há ressalvas. No governo federal inteiro, a relação se inverte e Lula gastou mais. Os valores também mudam conforme a correção pela inflação e a metodologia. O próprio Terra lembra que a CGU revisou o total de Bolsonaro para cerca de R$ 42 milhões a R$ 48 milhões. E o texto não menciona os 30%. A frase de Lula vale só para a Presidência e não diz qual recorte usou. | G92: Média | H92: Verdadeiro, mas impreciso | I92: Sim | J92: REAVALIADO SEM FONTES ENVIESADAS. O veredito não mudou. A Gazeta do Povo (excluída) foi retirada, e nenhum dado dela foi usado. Os percentuais anuais foram recalculados só com os números do Terra, e estão corretos. Revisor: Confirmei pelo WebFetch os números citados do Terra. Há uma ressalva: o Terra atribui os números da Secretaria ao Aos Fatos e os da Presidência ao Estadão Verifica, que são checagens, e não informa a fonte do total do governo federal. Ainda assim, a fonte usada é o Terra, um portal jornalístico, com dados que vêm do Portal da Transparência. Nenhuma fonte excluída foi usada. A confiança Média se justifica por essa origem indireta dos números e pela divergência de metodologias. | K92: https://www.terra.com.br/noticias/eleicoes/jair-bolsonaro-gastou-mais-no-cartao-corporativo-do-que-lula,4ffda9eadcc210176ff3273b5ac8f854m750onan.html https://portaldatransparencia.gov.br/cartoes

Sheet Promessas
A1: ID | B1: Candidato | C1: Tema | D1: Tempo no vídeo | E1: Promessa | F1: Viabilidade (%) | G1: Classificação | H1: Justificativa | I1: Custo estimado | J1: Fatores econômicos | K1: Fatores regionais | L1: Obstáculos (legais, políticos, técnicos) | M1: Confiança | N1: % análise inicial | O1: Nota do revisor independente | P1: Principais fontes | R1: Grupo do tema
A2: PF01 | B2: Flávio | C2: Infraestrutura | D2: 00:10 | E2: Concluir a Transnordestina até os portos de Suape (PE) e Pecém (CE). | F2: 0.25 | G2: =IF(F2>=0.7,"Alta",IF(F2>=0.4,"Média","Baixa")) | H2: Chegar a Pecém até 2030 é provável, mas não garantido, dado o histórico de atrasos. Terminar os cerca de 540 km até Suape em quatro anos, contratando só lotes isolados, é improvável. Como a promessa inclui os dois portos, a nota fica baixa. | I2: Não há custo total estimado para Salgueiro–Suape (cerca de 540 km). O único valor concreto é um contrato de R$ 312,8 milhões, assinado em julho de 2026, para 73,3 km entre Custódia e Arcoverde (Diário de Pernambuco). O ramal de Pecém é pago pela TLSA com recursos do FDNE. | J2: O eixo Eliseu Martins–Pecém estava cerca de 81% pronto em 2026, e o aditivo de 2022 dá prazo até por volta de 2029. Em Pernambuco, a União voltou a contratar obras em lotes (Custódia–Arcoverde), mas cada lote depende de dinheiro do orçamento, que é pouco dentro do arcabouço fiscal. | K2: Para Ceará e Piauí, a ferrovia escoa minério e grãos do MATOPIBA até o Pecém. Pernambuco e a FIEPE pressionam pelo ramal até Suape, mas a demanda de carga desse trecho é questionada desde 2022. | L2: Não exige PEC nem lei nova. Exige decisão do TCU (o ministro Jhonatan de Jesus pediu vista e a sessão foi remarcada para 14/10), definição do modelo para o trecho pernambucano, desapropriações e licenças. A obra começou em 2006, ficou parada em 2016 e já perdeu vários prazos. | M2: Média | N2: 0.3 | O2: Baixei de 30% para 25%. Ao reler a fonte, apareceu um fato que a análise original ignorou: em julho de 2026 houve contrato de R$ 312,8 milhões para 73 km no trecho pernambucano. Isso mostra que o trecho não está totalmente parado, mas também que avança em lotes pequenos, num ritmo incompatível com chegar a Suape até 2030. Também pesei o risco de atraso no próprio ramal de Pecém. Limitação: o limite de buscas da sessão acabou, então conferi lendo diretamente as fontes originais, sem fazer buscas novas. | P2: https://www.diariodepernambuco.com.br/economia/2026/10/11725523-analise-sobre-trecho-pernambucano-da-ferrovia-transnordestina-e-adiada-pelo-tcu.html https://diariodonordeste.verdesmares.com.br/negocios/transnordestina-veja-cronograma-das-obras-e-o-que-muda-com-aditivo-do-contrato-da-ferrovia-no-ce-1.3318404 https://www.diariodepernambuco.com.br/economia/2026/05/11714501-transnordestina-em-pernambuco-um-historico-de-decisoes-negativas.html https://www.diariodepernambuco.com.br/economia/2026/05/11714979-transnordestina-governo-e-empresarios-assinam-manifesto-pela-conclusao-do-trecho-salgueiro-suape.html | R2: Infraestrutura
A3: PF02 | B3: Flávio | C3: Infraestrutura / Sul | D3: 00:10 | E3: Construir o eixo sul ferroviário ligando o Centro-Oeste ao oeste do Paraná e de Santa Catarina (Nova Ferroeste). | F3: 0.05 | G3: =IF(F3>=0.7,"Alta",IF(F3>=0.4,"Média","Baixa")) | H3: Pelo próprio desenho contratual, o eixo completo não ficaria pronto antes de meados dos anos 2030, mesmo com leilão em 2027. No máximo, dá para fazer o leilão e começar as obras até 2030. | I3: R$ 35,8 bilhões para 1.567 km, incluindo material rodante, segundo o estudo de viabilidade (EVTEA). Lance mínimo de R$ 110 milhões e concessão de 99 anos (AEN-PR). | J3: O projeto depende quase todo de capital privado e ainda não tem leilão marcado. Com juros altos, é difícil financiar uma obra desse tamanho, e um aporte federal relevante não cabe no arcabouço fiscal. | K3: A ferrovia ligaria Maracaju (MS), o oeste do Paraná e Chapecó (SC) a Paranaguá, passando por 67 municípios. É uma região forte em grãos e proteína animal que hoje depende de caminhões. O traçado passa por terras indígenas no MS e pela Serra do Mar. | L3: A Licença Prévia ainda está em análise no Ibama. Depois do leilão, o projeto executivo leva cerca de 2 anos, e só então vem a Licença de Instalação. O próprio edital prevê, nos primeiros 7 anos, só o trecho Paranaguá–Guarapuava e a melhoria de Guarapuava–Cascavel. Os outros trechos só ganham cronograma depois que a operação começar. A concessão é estadual (Paraná) e envolve três estados, então a União tem pouco controle. | M3: Alta | N3: 0.08 | O3: Baixei de 8% para 5%. O edital, que a análise original não detalhou, já prevê só o primeiro trecho nos primeiros 7 anos e 2 anos de projeto executivo antes da Licença de Instalação. Isso torna a conclusão até 2030 praticamente impossível no papel. Os dados de custo da análise original foram confirmados em fonte oficial (AEN-PR). Não foi possível fazer buscas novas porque o limite da sessão acabou. | P3: https://www.parana.pr.gov.br/aen/Noticia/Perguntas-e-respostas-conheca-os-detalhes-do-edital-da-Nova-Ferroeste https://www.parana.pr.gov.br/aen/Noticia/Estado-divulga-o-edital-da-Nova-Ferroeste-ligacao-ferroviaria-que-vai-transformar-o https://www.campograndenews.com.br/economia/para-estudos-de-terra-indigena-em-ms-leilao-da-nova-ferroeste-ficara-para-2025 https://www.semadesc.ms.gov.br/?p=120681 | R3: Infraestrutura
A4: PF03 | B4: Flávio | C4: Infraestrutura / Centro-Oeste | D4: 00:11 | E4: Concluir a FICO (Ferrovia de Integração Centro-Oeste) e a FIOL (Ferrovia de Integração Oeste-Leste). | F4: 0.12 | G4: =IF(F4>=0.7,"Alta",IF(F4>=0.4,"Média","Baixa")) | H4: FICO 1 e FIOL II podem ficar prontas até 2030. Mas o próprio governo fala em 2033 para a FIOL 1 e em 2037–2038 para o corredor completo, o que torna a conclusão das duas ferrovias no mandato muito improvável. | I4: Parcial: FIOL 1 com Porto Sul custa cerca de R$ 7 bilhões, segundo o ministro dos Transportes (Agência Infra). O lote 05FC da FIOL II custa R$ 467,9 milhões. A FICO 1 é paga pela Vale como contrapartida da renovação da EFVM. FIOL 3 e FICO 2 não têm orçamento. | J4: A FIOL II tinha cerca de 71% de execução física, e o governo prevê leiloá-la. A FIOL 1 deve passar da Bamin, que está inadimplente, para a Mota-Engil, com entrega prevista para 2033. A extensão da FICO 2 até Lucas do Rio Verde é investimento não obrigatório e depende de acordo com a operadora. Segundo o ministro, o corredor inteiro só fica pronto entre 2037 e 2038. | K4: O eixo atende o oeste da Bahia, o norte de Goiás e o leste de Mato Grosso, regiões de grãos e minério, e daria saída pelo Porto Sul (Ilhéus) com ligação à Norte-Sul. | L4: Depende da troca de concessionário com aval da ANTT, do leilão da FIOL II, de projeto e licenças da FIOL 3 (cerca de 900 km), de auditorias do TCU (contrato do Lote 5F encerrado com 64,66% executado) e de acordo com a Vale para a FICO 2. Não exige PEC. | M4: Média | N4: 0.15 | O4: Baixei de 15% para 12%. A mesma fonte usada pela análise original traz a previsão oficial de conclusão do corredor inteiro entre 2037 e 2038, que a análise não usou. Ela também diz que a FICO 2 é investimento não obrigatório e que a FIOL 3 só começa depois da FIOL 2. Sem buscas novas, porque o limite da sessão acabou. | P4: https://agenciainfra.com/blog/mota-engil-aguarda-autorizacao-da-antt-para-assumir-fiol-1-diz-ministro/ https://static.poder360.com.br/uploads/2026/10/001.733-2026-5-ASC-auditoria_Fiol_Lote-5F.pdf https://www.bnews.com.br/noticias/politica/governo-lanca-edital-de-meio-bilhao-para-concluir-obras-da-fiol-na-bahia.html https://www.gov.br/transportes/pt-br/assuntos/incentivos/incentivos-fiscais/reidi-requerimento-e-consulta/Portarian502de27abr2021ValecFIOLReidiDOU29abr2021.pdf | R4: Infraestrutura
A5: PF04 | B5: Flávio | C5: Infraestrutura | D5: 00:10 | E5: Ampliar concessões de rodovias com pedágio zero para motocicletas em todas elas, e continuar concessões de portos. | F5: 0.45 | G5: =IF(F5>=0.7,"Alta",IF(F5>=0.4,"Média","Baixa")) | H5: Continuar as concessões é quase certo, e a isenção nas concessões federais novas é factível. Isentar motos em todas as rodovias, incluindo contratos vigentes e rodovias estaduais, esbarra em contratos e na divisão de competências. A frase da promessa é ambígua e pode se referir só às novas concessões, o que a deixaria no meio da faixa. | I5: Não estimável. Isentar motos nos contratos já em vigor exige reequilíbrio econômico-financeiro, com aumento da tarifa dos outros veículos, mais prazo de concessão ou compensação da União. O impacto depende da participação das motos na receita de cada praça. | J5: As concessões de rodovias e portos seguiram em governos de linhas diferentes, então essa parte é muito viável. A isenção geral não tem lei aprovada. O PL 312/2026, do senador Cleitinho (Republicanos/MG), prevê isenção em todas as rodovias, mas está 'aguardando despacho' desde 04/02/2026. | K5: A medida é nacional, com peso maior no Sul e no Sudeste, onde se concentram as rodovias pedagiadas. Beneficia motociclistas de entrega e quem usa a moto para ir trabalhar. | L5: Nas concessões federais novas, basta prever a isenção no edital. Nos contratos vigentes, é preciso lei ou renegociação com reequilíbrio, com risco de disputa judicial. Rodovias estaduais concedidas são de competência dos estados. Leilões de portos dependem da ANTAQ e do TCU. | M5: Média | N5: 0.45 | O5: Mantive 45%. Confirmei no site do Senado que o PL 312/2026 é do senador Cleitinho e está aguardando despacho desde fevereiro de 2026. A fonte da ALMT usada na análise original não foi verificada. A ambiguidade da promessa ('todas elas' pode significar só as novas concessões) foi registrada, mas não muda a nota. Sem buscas novas, porque o limite da sessão acabou. | P5: https://www25.senado.leg.br/web/atividade/materias/-/materia/172564 https://www12.senado.leg.br/ecidadania/visualizacaomateria?id=172564 https://www.al.mt.gov.br/storage/webdisco/cp/20260615104430170100.pdf | R5: Infraestrutura
A6: PF05 | B6: Flávio | C6: Infraestrutura / Conectividade | D6: 00:10 | E6: Tratar internet como infraestrutura e levar conexão a escolas, unidades de saúde e aldeias indígenas, inclusive para agricultura de precisão. | F6: 0.62 | G6: =IF(F6>=0.7,"Alta",IF(F6>=0.4,"Média","Baixa")) | H6: Escolas e unidades de saúde devem avançar bastante até 2030. Mas a meta anterior (2026) foi perdida, o ritmo de cerca de 5 mil escolas por ano teria de dobrar, e a parte de aldeias e agricultura de precisão tende a ficar parcial. Por isso a nota fica no alto da faixa Média, e não na Alta. | I6: Cerca de R$ 8,8 a 9 bilhões na Estratégia Nacional de Escolas Conectadas, dos quais cerca de R$ 6,5 bilhões vêm do Novo PAC. Há também recursos do Fust e obrigações do leilão do 5G. O MME leva energia, via PAC, às escolas que não têm. Fontes: MCom/MEC, citados pela imprensa. | J6: É uma política já em andamento e paga em boa parte por fundos setoriais e obrigações das operadoras. Mas a meta oficial era conectar as 138,3 mil escolas até 2026, e só cerca de 99 mil estavam conectadas em 2026 (eram cerca de 94 mil em 2025). Ou seja, a meta foi descumprida e o ritmo foi de cerca de 5 mil escolas por ano. | K6: As maiores lacunas estão no Norte (20,4 mil escolas na meta; no Acre, menos da metade conectada) e no Nordeste rural (49,9 mil escolas). Aldeias dependem de satélite e, às vezes, de levar energia primeiro. A cobertura 4G/5G no campo para agricultura de precisão ainda é baixa. | L6: Não exige mudança na lei. Exige coordenação entre MEC, MCom, MME, estados e municípios, logística na Amazônia, contratos de manutenção e pagamento contínuo do serviço. A cobertura rural depende do calendário de obrigações do 5G. | M6: Média | N6: 0.72 | O6: Baixei de 72% para 62%, saindo da faixa Alta para a Média. A fonte original (2023) mostra que a meta era universalizar o acesso nas escolas até 2026, e isso não aconteceu. Esse histórico de execução foi ignorado pela análise original e, pela mesma régua usada nas ferrovias, pesa contra a nota. Para cumprir até 2030, o ritmo teria de dobrar. Sem buscas novas, porque o limite da sessão acabou. | P6: https://www.itatiaia.com.br/politica/governo-federal-lanca-escolas-conectadas-meta-e-ter-1388-mil-escolas-publicas-com-internet-de-qualidade-ate-2026/ https://brasil61.com/n/internet-chega-a-quase-metade-das-escolas-publicas-do-acre-mcom260240 https://brasil61.com/n/internet-chega-a-mais-da-metade-das-escolas-publicas-do-amazonas-mcom260243 https://www.conexaoto.com.br/2026/04/11/tocantins-supera-70-das-escolas-publicas-conectadas-a-internet | R6: Infraestrutura
A7: PF06 | B7: Flávio | C7: Economia / Renda | D7: 00:28 | E7: Reajustar salário mínimo, aposentadorias, BPC e aposentadoria rural acima da inflação, e não privatizar Banco do Brasil, Caixa e Petrobras. | F7: 0.68 | G7: =IF(F7>=0.7,"Alta",IF(F7>=0.4,"Média","Baixa")) | H7: Para cumprir o núcleo da promessa (mínimo, BPC e aposentadoria rural acima da inflação e não privatizar) basta manter o que já existe, e Flávio reafirmou isso na sabatina de 16/10. Ele também disse que manterá o ganho real para aposentados 'como ocorre hoje', o que limita a promessa ao piso. O risco que resta é a pressão fiscal pela desindexação e a leitura ampla de 'todas as aposentadorias'. | I7: Cada R$ 1 a mais no salário mínimo custa cerca de R$ 413 milhões por ano (PLOA 2027, segundo SBT News, que cita o Ministério da Fazenda). O PLOA 2027 prevê mínimo de R$ 1.741, alta de R$ 120 (7,4%) sobre os R$ 1.621 atuais. Manter a regra atual não cria custo além do que já está projetado. Dar ganho real a todas as aposentadorias acima do piso seria custo novo de dezenas de bilhões por ano; não estimado oficialmente. | J7: O PLOA 2027 prevê receita líquida de R$ 2,849 trilhões e despesa de R$ 2,83 trilhões. A meta de primário é de R$ 73,2 bilhões, e o governo projeta R$ 83,4 bilhões após deduções. A regra atual (Lei 14.663/2023, com limite de 0,6% a 2,5% de ganho real fixado pela Lei 15.077/2024) já garante ganho real ao piso e aos benefícios vinculados a ele. A fonte de 'mais de R$ 200 bilhões por ano' que Flávio citou é a securitização de créditos da União (O Liberal, 16/10/2026). Essa receita é financeira e não amplia o limite de despesa do arcabouço. | K7: O alcance é nacional, mas o peso é maior no Nordeste, no Norte e nos municípios pequenos, onde BPC e aposentadoria rural de um salário mínimo são parte central da renda local. | L7: Manter a regra atual não exige nada, e não privatizar BB, Caixa e Petrobras depende só do Executivo. A pressão crescente da regra do mínimo sobre a Previdência e o BPC, num quadro de discricionárias espremidas, pode levar o próximo governo a rever a indexação, e o mercado cobra isso. Ganho real para todas as aposentadorias exigiria lei e espaço no teto. | M7: Média | N7: 0.62 | O7: Subi de 62 para 68. A análise original tratou os 'R$ 200 bilhões' como um ajuste de corte de gastos que entraria em choque com a promessa. Segundo O Liberal, porém, o valor é receita prometida com securitização de créditos da União, não corte. Na mesma sabatina, Flávio se comprometeu a manter o ganho real dos aposentados 'como ocorre hoje' e disse que não vai desvincular. Com isso, a promessa se aproxima de manter o que já existe e o choque com a promessa fiscal fica menor do que o original afirmou. Fiz uma correção: a fonte SBT não menciona aposentadorias nem BPC e não traz o R$ 200 bi. Também não consegui confirmar a afirmação de que ele evitou o compromisso em agosto. Fica em Média, no limite da faixa, porque a indexação deve sofrer pressão fiscal até 2030. | P7: https://www.congressoemfoco.com.br/noticia/121825/projeto-de-orcamento-de-2027-preve-salario-minimo-de-r-1-741 https://www.oliberal.com/politica/flavio-diz-que-nao-vai-desvincular-reajuste-do-minimo-e-nem-alterar-pisos-de-saude-e-educacao-1.1183567 https://sbtnews.sbt.com.br/noticia/eleicoes/flavio-promete-reajuste-do-minimo-acima-da-inflacao https://sbtnews.sbt.com.br/noticia/politica/salario-minimo-de-2027-sera-de-r-1-741-diz-durigan | R7: Economia
A8: PF07 | B8: Flávio | C8: Mobilidade | D8: 00:17 | E8: Apoiar tarifa zero nos ônibus nos fins de semana. | F8: 0.3 | G8: =IF(F8>=0.7,"Alta",IF(F8>=0.4,"Média","Baixa")) | H8: A proposta não tem fonte de financiamento nem instrumento legal definidos, gera custo bilionário recorrente dentro do arcabouço e a competência é municipal. A adesão de Flávio é recente e genérica, então uma tarifa zero nacional nos fins de semana até 2030 é pouco provável. | I8: De R$ 12 bilhões por ano (governo) a R$ 20,8 bilhões por ano (NTU, Diário do Transporte e DGABC). O deputado Jilmar Tatto estima R$ 16 bilhões por ano, cerca de 26% dos R$ 61 bilhões em emendas de 2026 (Congresso em Foco). | J8: Seria uma despesa nova e permanente, que teria de caber no teto do arcabouço, num PLOA 2027 já apertado. Flávio não indicou fonte de financiamento. A PEC de Lula financia a medida com emendas parlamentares, e para o Congresso isso custa poder político. | K8: O transporte coletivo é competência municipal (art. 30, V, da CF). As experiências de tarifa zero existentes estão concentradas em municípios pequenos e médios. Nas metrópoles do Sudeste o custo por município é muito maior e há contratos de concessão em vigor. | L8: Uma fonte federal permanente exige PEC (308 votos na Câmara e 49 no Senado, em dois turnos) ou lei com fonte definida e repasse aos municípios. Os contratos de concessão precisariam ser reequilibrados. 'Apoiar' é um compromisso fraco: se a medida não sair, fica difícil responsabilizar o candidato. | M8: Média | N8: 0.32 | O8: Baixei de 32 para 30 e mantive na faixa Baixa. Confirmei o custo (R$ 16 bi por ano, 26% das emendas) e o quórum da PEC no Congresso em Foco. Não consegui confirmar duas afirmações do original: que o presidente da Câmara 'já resiste' e que a PEC foi enviada em 21/10 (a reportagem de 15/10 diz que o texto ainda não tinha sido apresentado). Por isso não as usei como base. O pequeno ajuste para baixo vem de dois pontos: falta qualquer fonte de financiamento proposta por Flávio e o verbo 'apoiar' é fraco. Para ser coerente, a mesma promessa de Lula deve ser avaliada com o mesmo obstáculo de PEC e financiamento. | P8: https://www.congressoemfoco.com.br/noticia/123316/lula-propoe-usar-emendas-para-financiar-tarifa-zero-aos-fins-de-semana https://diariodotransporte.com.br/2026/10/16/tarifa-zero-aos-fins-de-semana-pode-custar-r-208-bilhoes-por-ano-calcula-ntu/ https://www.dgabc.com.br/Noticia/4354042/tarifa-zero-governo-preve-r$-12-bi-mas-setor-estima-r$-20-8-bi https://timesbrasil.com.br/brasil/lula-diz-que-enviara-pec-da-tarifa-zero-ao-congresso-nesta-quarta-21-custo-pode-atingir-r-16-bilhoes-anuais/ | R8: Mobilidade
A9: PF08 | B9: Flávio | C9: Agro / Centro-Oeste | D9: 00:24 | E9: Aprovar lei que proíba contingenciar recursos do seguro rural e do Plano Safra; dar previsibilidade e segurança jurídica ao agro; digitalizar a concessão da aposentadoria rural. | F9: 0.64 | G9: =IF(F9>=0.7,"Alta",IF(F9>=0.4,"Média","Baixa")) | H9: A blindagem legal tem custo baixo, base parlamentar forte e precedente, e a digitalização é administrativa. A blindagem só pelo contingenciamento, porém, pode não evitar os bloqueios do arcabouço, que foi o que cortou o PSR em 2026, e a parte de 'segurança jurídica' é vaga. Por isso fica na faixa média-alta, e não na Alta. | I9: Blindar o PSR custa pouco no total: o bloqueio de 2026 foi de cerca de R$ 518 milhões (R$ 461,7 milhões mais R$ 56 milhões), e o setor pede cerca de R$ 4 bilhões por ano. A equalização de juros do Plano Safra, que tem R$ 525 bilhões em crédito no ciclo 2026/27, custa bilhões por ano. Digitalizar a aposentadoria rural tem custo baixo. | J9: Excluir essas despesas dos cortes não aumenta o teto do arcabouço (LC 200/2023), só transfere o corte para outras discricionárias. É preciso distinguir dois mecanismos. O contingenciamento (art. 9 da LRF) responde a frustração de receita. O bloqueio responde ao limite de despesa do arcabouço. Os cortes do PSR em 2026 foram atribuídos a 'restrições fiscais', e uma lei que proíba só o contingenciamento pode não impedir o bloqueio. | K9: O Centro-Oeste (MT, GO, MS) e o Sul (RS, PR) concentram a demanda por seguro rural e crédito. No Sul as perdas climáticas se repetem, e o agro goiano reclamou de menos crédito no ciclo 2026/27. | L9: Mexer na LRF exige lei complementar (maioria absoluta: 257 deputados e 41 senadores). A Frente Parlamentar da Agropecuária (FPA) tem base ampla e há precedente: a LC 177/2021 blindou o FNDCT. Para valer de fato, a proteção teria de alcançar também o bloqueio pelo teto, e a equipe econômica resistiria. 'Previsibilidade e segurança jurídica' não é mensurável. A digitalização depende do INSS, que já usa autodeclaração e CNIS rural, então a promessa é em parte algo já em curso. | M9: Média | N9: 0.7 | O9: Baixei de 70 para 64 e passei de Alta para Média por três motivos. Primeiro, a análise original não distinguiu contingenciamento (LRF) de bloqueio (teto do arcabouço), e foi o bloqueio que atingiu o PSR em 2026. Uma lei que proíba só o contingenciamento pode deixar a promessa sem efeito. Segundo, não consegui confirmar a tramitação do projeto de Tereza Cristina citado no original: a busca estava sem saldo e o site do Canal Rural retornou erro 403. Terceiro, descartei a fonte cnabrasil.org.br, que é de entidade de classe, não é oficial nem jornalística. | P9: https://www.canalrural.com.br/politica/bloqueio-de-r-4617-milhoes-no-psr-e-atribuido-a-restricoes-fiscais/ https://comprerural.com/governo-bloqueia-mais-r-56-milhoes-do-seguro-rural-as-vesperas-do-plano-safra-2026-27/ https://www.jornalopcao.com.br/ultimas-noticias/plano-safra-2026-2027-anuncia-r-525-bilhoes-agro-de-goias-ve-reducao-do-credito-e-cobra-seguro-rural-842176/ https://cnabrasil.org.br/noticias/sistema-faep-pede-r-670-bilhoes-no-plano-safra-2026-27 | R9: Agro
A10: PF09 | B10: Flávio | C10: Segurança / Fronteiras | D10: 00:25 | E10: Fazer pacto com governadores do Centro-Oeste contra o crime organizado e as rotas de tráfico nas fronteiras. | F10: 0.68 | G10: =IF(F10>=0.7,"Alta",IF(F10>=0.4,"Média","Baixa")) | H10: O núcleo da promessa é firmar um pacto com governadores. Isso cabe ao Executivo, tem precedentes e conta com governadores motivados pela escalada da violência na fronteira de MS. A probabilidade de cumprimento formal é alta. Reduzi a nota de 72 para 68 (limite superior da faixa Média) porque 'substancialmente cumprida' supõe ação contínua contra as rotas. O plano associado (força militar de fronteira, dobrar o investimento) não tem financiamento definido, e a PEC da Segurança está parada no plenário do Senado. Também não encontrei, nas fontes abertas, o pacto com governadores do Centro-Oeste citado como item do plano de Flávio: a reportagem do Correio do Estado sobre as propostas de fronteira não fala em 'pacto'. | I10: Baixo para formalizar o pacto, que é um acordo político e administrativo. Para operar de fato (Ficco, inteligência integrada, efetivo da PF/PRF/Forças Armadas na faixa de fronteira, tecnologia de vigilância), algumas centenas de milhões a poucos bilhões de reais por ano. A 'força de elite' de fronteira que o plano de Flávio propõe e a promessa de dobrar o investimento federal em segurança em quatro anos ficariam bem acima disso, e o candidato não indicou de onde viria o dinheiro. | J10: É despesa discricionária disputada dentro do arcabouço fiscal. Segundo o Correio do Estado (19/10/2026), Flávio cita dados da Fazenda de que a União destina 0,4% dos gastos à segurança e promete dobrar o investimento sem detalhar as fontes. O FNSP, as emendas e a estrutura federal já existente (programa Brasil Contra o Crime Organizado, lançado em maio de 2026, e as Ficco) dão base para operações conjuntas sem lei nova. | K10: MS e MT fazem fronteira com Paraguai e Bolívia. Segundo o Correio do Estado (out/2026), a fronteira sul-mato-grossense vive uma guerra crescente entre CV e PCC pelo controle do tráfico, o que deixa os governadores interessados em cooperar. GO e DF funcionam como corredores logísticos. Os governadores eleitos em 2026 tomam posse junto com o presidente, e o alinhamento político da região tende a favorecer um pacto com um governo do PL. | L10: Pelo art. 144 da CF, a segurança pública é sobretudo dos estados: a União coordena, mas não comanda as polícias estaduais. A PEC 18/2025, que reforçaria a coordenação federal, foi aprovada na CCJ do Senado, mas a votação em plenário saiu da pauta (Correio do Estado, 19/10/2026). Faltam efetivo e continuidade orçamentária. Iniciativas anteriores para a fronteira (ENAFRON, PEF, PPIF) tiveram resultados limitados. Assinar o pacto é fácil; o difícil é reduzir as rotas de forma mensurável. | M10: Média | N10: 0.72 | O10: RECHECADO (2ª rodada). Fiz só 1 das 3 buscas planejadas: o limite de buscas da sessão (200, compartilhado entre os agentes) acabou nas consultas seguintes. Abri e confirmei três páginas: Correio do Estado (19/10/2026), Reuters via Internazionale (18/06/2026) e CNN Brasil (28/05/2026). Fatos novos de 2026 que o agente original não tinha: o programa Brasil Contra o Crime Organizado (maio de 2026), a situação da PEC 18/2025 (aprovada na CCJ, retirada da pauta do plenário pelo presidente do Senado), o plano de Flávio com força de elite de fronteira e a meta de dobrar o investimento sem fonte indicada, e a escalada CV x PCC em MS. A nota cai 4 pontos, de Alta para Média, porque a promessa depende de financiamento não especificado e a PEC está travada. Não consegui abrir páginas oficiais da Câmara/Senado (proposição errada ou domínio inacessível). | P10: https://correiodoestado.com.br/cidades/conflito-na-fronteira-ocupa-espaco-entre-as-propostas-dos-candidatos-a/475016/ https://www.internazionale.it/ultime-notizie-reuters/2026/06/18/brazil-s-flavio-bolsonaro-pitches-crime-crackdown-to-boost-presidential-bid https://www.cnnbrasil.com.br/politica/grande-dia-diz-flavio-apos-eua-classificarem-pcc-e-cv-como-terroristas/ | R10: Segurança
A11: PF10 | B11: Flávio | C11: Sul / RS | D11: 00:31 | E11: Ajudar o RS a sair da dívida com a União e financiar bombas d'água e comportas contra enchentes em Porto Alegre e região. | F11: 0.43 | G11: =IF(F11>=0.7,"Alta",IF(F11>=0.4,"Média","Baixa")) | H11: A parte das obras (bombas, comportas, diques) é viável até 2030. O custo é pequeno perto do orçamento federal, e em jul/2024 a União liberou R$ 6,5 bilhões para macrodrenagem no RS, dos quais R$ 2 bilhões para a Região Metropolitana de Porto Alegre. A execução, porém, está atrasada: um ano depois esses recursos não tinham sido usados e uma licitação fracassou. 'Ajudar a sair da dívida' tende a se resumir a implementar o Propag, que o RS já pediu. Quitar ou eliminar uma dívida de R$ 106,5 bilhões até 2030 é inviável. A média das duas partes fica na faixa média. As fontes OK confirmam os dados centrais. | I11: A dívida do RS com a União é de R$ 106,5 bilhões. O Estado pediu abatimento de 20% (cerca de R$ 21 bilhões), pago com cessão de FPE futuro (R$ 12,8 bilhões entre 2032 e 2055), recebíveis do FNDR (R$ 6,6 bilhões entre 2029 e 2055) e crédito da Corsan (R$ 1,8 bilhão). A Prefeitura orça em R$ 401 milhões os reparos do sistema de Porto Alegre. Há ainda R$ 2 bilhões federais destinados à RMPA para diques, comportas e bombas. | J11: O RS pediu adesão ao Propag (LC 212/2025), no 'pacote 1', com juro real zero. O saldo segue corrigido monetariamente, e parte da correção vai ao Fundo de Equalização Federativa e a investimentos no Estado. A Sefaz-RS projeta economia de R$ 42 bilhões nominais até 2057. O Tesouro calcula que o RS deixaria de pagar R$ 45 bilhões entre 2027 e 2035, e que o estoque, que poderia chegar a R$ 140 bilhões, cairia para R$ 112 bilhões. Os pagamentos estão suspensos até 2027 por causa das enchentes (cerca de R$ 14 bilhões poupados), e até lá o RS está dispensado de aportes ao Fundo. Perdoar ou quitar a dívida teria custo fiscal alto para a União e abriria precedente para outros estados. Financiar bombas e comportas é barato em comparação. | K11: O sistema de Porto Alegre foi projetado na década de 1970 e tem 68 km de diques, 23 casas de bombas e 14 comportas. Na enchente de 2024, 19 das 23 casas de bombas foram desligadas. Dos 309 equipamentos públicos destruídos, 278 estão em funcionamento, segundo a Prefeitura. Um ano depois, a licitação para elevar os painéis elétricos tinha fracassado, a obra dos diques estava parada em trechos com famílias morando em cima, e as comportas 11 a 14 ainda eram fechadas com sacos de areia e argila. Eldorado do Sul só tem planejado um dique de quase 9 km. | L11: Tirar o RS da dívida além do Propag exige lei complementar e tratamento isonômico entre os estados, o que enfrenta resistência federativa e fiscal. As obras anticheias são executadas por estado e município e dependem de projeto, licitação (uma já fracassou), reassentamento de famílias e licenciamento. O histórico recente é de atraso. | M11: Alta | N11: 0.43 | O11: REAVALIADO SEM FONTES ENVIESADAS. A viabilidade (43%) e a confiança se mantêm. Ajustes de precisão em relação ao texto do outro agente: (1) o sistema foi 'projetado' nos anos 1970, como diz a Prefeitura, e não 'começou a ser construído'; (2) foram retirados dois dados que não aparecem em nenhuma fonte OK: o juro real anterior de 4% e a adesão ficta até maio/2027; (3) 278 equipamentos 'estão em funcionamento', e não 'voltam a funcionar'; (4) os R$ 6,5 bilhões e os R$ 2 bilhões não usados vêm do Poder360, e não do SBT. Revisor: Abri as cinco fontes OK. O Governo do RS confirma a dívida de R$ 106,5 bilhões, os 20%, o FPE, o FNDR, a Corsan e os R$ 42 bilhões. A Folha PE confirma os R$ 45 bilhões entre 2027 e 2035 e a dispensa de aportes até 2027. O SBT confirma 19 de 23 casas de bombas desligadas, a licitação fracassada, os diques parados por famílias e o dique de 9 km em Eldorado. O Poder360 confirma os sacos de areia e os R$ 2 bilhões de um total de R$ 6,5 bilhões sem uso. A Prefeitura confirma os R$ 401 milhões, os números 309/278 e os 68 km, 23 casas de bombas e 14 comportas. | P11: https://estado.rs.gov.br/governo-do-estado-encaminha-a-uniao-pedido-de-adesao-ao-propag https://prefeitura.poa.br/gp/noticias/prefeito-reafirma-pedido-de-recursos-do-estado-para-obras-de-protecao-contra-cheias https://www.folhape.com.br/economia/ceron-esclarece-que-rs-esta-dispensado-de-aportes-a-fundo-do-propag/386185/ https://sbtnews.sbt.com.br/noticia/brasil/sistema-anticheias-de-porto-alegre-tem-obras-paralisadas-um-ano-apos-a-tragedia | R11: Sul
